Workbook

Sheet WBS
A1: 序號 | B1: 工作項目 | C1: 隸屬系統 | D1: 預計開始日期 | E1: 預計完成日期 | F1: 實際開始日期 | G1: 實際完成日期 | H1: Owner | I1: 協助者 | J1: 進度 | K1: 說明
A2: 1 | B2: 開發 YMS302W 抽選稽核紀錄 (YMS302P8) | C2: YMS | D2: 45811 | E2: 45817 | F2: 45811 | H2: 莊勝淵 | I2: 陸德軒 | J2: =IF(LEN($G2)=0,IF(進度管制表!$D$1>$E2,"延遲","未完成"),IF($E2=$G2,"如期完成",(IF($E2>$G2,"提前完成",IF($E2<$G2,"落後且完成","未完成"))))) -> 未完成 | L2: 應用系統YMS開發測試
A3: 2 | B3: 初測 YMS302W 抽選稽核紀錄 (YMS302P8) | C3: YMS | D3: 45818 | E3: 45818 | H3: 莊勝淵 | J3: =IF(LEN($G3)=0,IF(進度管制表!$D$1>$E3,"延遲","未完成"),IF($E3=$G3,"如期完成",(IF($E3>$G3,"提前完成",IF($E3<$G3,"落後且完成","未完成"))))) -> 未完成 | L3: 應用系統YMS開發測試
A4: 3 | B4: 修正初測問題 YMS302W 抽選稽核紀錄 (YMS302P8) | C4: YMS | D4: 45818 | E4: 45818 | H4: 莊勝淵 | I4: 陸德軒 | J4: =IF(LEN($G4)=0,IF(進度管制表!$D$1>$E4,"延遲","未完成"),IF($E4=$G4,"如期完成",(IF($E4>$G4,"提前完成",IF($E4<$G4,"落後且完成","未完成"))))) -> 未完成 | L4: 應用系統YMS開發測試
A5: 4 | B5: 開發 YMS302W 抽選稽核紀錄 (YMS302P14) | C5: YMS | D5: 45819 | E5: 45821 | H5: 莊勝淵 | I5: 陸德軒 | J5: =IF(LEN($G5)=0,IF(進度管制表!$D$1>$E5,"延遲","未完成"),IF($E5=$G5,"如期完成",(IF($E5>$G5,"提前完成",IF($E5<$G5,"落後且完成","未完成"))))) -> 未完成 | L5: 應用系統YMS開發測試
A6: 5 | B6: 初測 YMS302W 抽選稽核紀錄 (YMS302P14) | C6: YMS | D6: 45824 | E6: 45824 | H6: 莊勝淵 | J6: =IF(LEN($G6)=0,IF(進度管制表!$D$1>$E6,"延遲","未完成"),IF($E6=$G6,"如期完成",(IF($E6>$G6,"提前完成",IF($E6<$G6,"落後且完成","未完成"))))) -> 未完成 | L6: 應用系統YMS開發測試
A7: 6 | B7: 修正初測問題 YMS302W 抽選稽核紀錄 (YMS302P14) | C7: YMS | D7: 45824 | E7: 45824 | H7: 莊勝淵 | I7: 陸德軒 | J7: =IF(LEN($G7)=0,IF(進度管制表!$D$1>$E7,"延遲","未完成"),IF($E7=$G7,"如期完成",(IF($E7>$G7,"提前完成",IF($E7<$G7,"落後且完成","未完成"))))) -> 未完成 | L7: 應用系統YMS開發測試
A8: 7 | B8: 開發 YMS302W 抽選稽核紀錄 (YMS302P15) | C8: YMS | D8: 45825 | E8: 45827 | H8: 莊勝淵 | I8: 陸德軒 | J8: =IF(LEN($G8)=0,IF(進度管制表!$D$1>$E8,"延遲","未完成"),IF($E8=$G8,"如期完成",(IF($E8>$G8,"提前完成",IF($E8<$G8,"落後且完成","未完成"))))) -> 未完成 | L8: 應用系統YMS開發測試
A9: 8 | B9: 初測 YMS302W 抽選稽核紀錄 (YMS302P15) | C9: YMS | D9: 45828 | E9: 45828 | H9: 莊勝淵 | J9: =IF(LEN($G9)=0,IF(進度管制表!$D$1>$E9,"延遲","未完成"),IF($E9=$G9,"如期完成",(IF($E9>$G9,"提前完成",IF($E9<$G9,"落後且完成","未完成"))))) -> 未完成 | L9: 應用系統YMS開發測試
A10: 9 | B10: 修正初測問題 YMS302W 抽選稽核紀錄 (YMS302P15) | C10: YMS | D10: 45828 | E10: 45828 | H10: 莊勝淵 | I10: 陸德軒 | J10: =IF(LEN($G10)=0,IF(進度管制表!$D$1>$E10,"延遲","未完成"),IF($E10=$G10,"如期完成",(IF($E10>$G10,"提前完成",IF($E10<$G10,"落後且完成","未完成"))))) -> 未完成 | L10: 應用系統YMS開發測試
A11: 10 | B11: 開發 YMS302W 抽選稽核紀錄 (YMS302P16) | C11: YMS | D11: 45831 | E11: 45833 | H11: 莊勝淵 | I11: 陸德軒 | J11: =IF(LEN($G11)=0,IF(進度管制表!$D$1>$E11,"延遲","未完成"),IF($E11=$G11,"如期完成",(IF($E11>$G11,"提前完成",IF($E11<$G11,"落後且完成","未完成"))))) -> 未完成 | L11: 應用系統YMS開發測試
A12: 11 | B12: 初測 YMS302W 抽選稽核紀錄 (YMS302P16) | C12: YMS | D12: 45834 | E12: 45834 | H12: 莊勝淵 | J12: =IF(LEN($G12)=0,IF(進度管制表!$D$1>$E12,"延遲","未完成"),IF($E12=$G12,"如期完成",(IF($E12>$G12,"提前完成",IF($E12<$G12,"落後且完成","未完成"))))) -> 未完成 | L12: 應用系統YMS開發測試
A13: 12 | B13: 修正初測問題 YMS302W 抽選稽核紀錄 (YMS302P16) | C13: YMS | D13: 45834 | E13: 45834 | H13: 莊勝淵 | I13: 陸德軒 | J13: =IF(LEN($G13)=0,IF(進度管制表!$D$1>$E13,"延遲","未完成"),IF($E13=$G13,"如期完成",(IF($E13>$G13,"提前完成",IF($E13<$G13,"落後且完成","未完成"))))) -> 未完成 | L13: 應用系統YMS開發測試
A14: 13 | B14: 開發 YMS302W 抽選稽核紀錄 (YMS302P17) | C14: YMS | D14: 45835 | E14: 45839 | H14: 莊勝淵 | I14: 陸德軒 | J14: =IF(LEN($G14)=0,IF(進度管制表!$D$1>$E14,"延遲","未完成"),IF($E14=$G14,"如期完成",(IF($E14>$G14,"提前完成",IF($E14<$G14,"落後且完成","未完成"))))) -> 未完成 | L14: 應用系統YMS開發測試
A15: 14 | B15: 初測 YMS302W 抽選稽核紀錄 (YMS302P17) | C15: YMS | D15: 45840 | E15: 45840 | H15: 莊勝淵 | J15: =IF(LEN($G15)=0,IF(進度管制表!$D$1>$E15,"延遲","未完成"),IF($E15=$G15,"如期完成",(IF($E15>$G15,"提前完成",IF($E15<$G15,"落後且完成","未完成"))))) -> 未完成 | L15: 應用系統YMS開發測試
A16: 15 | B16: 修正初測問題 YMS302W 抽選稽核紀錄 (YMS302P17) | C16: YMS | D16: 45840 | E16: 45840 | H16: 莊勝淵 | I16: 陸德軒 | J16: =IF(LEN($G16)=0,IF(進度管制表!$D$1>$E16,"延遲","未完成"),IF($E16=$G16,"如期完成",(IF($E16>$G16,"提前完成",IF($E16<$G16,"落後且完成","未完成"))))) -> 未完成 | L16: 應用系統YMS開發測試
A17: 16 | B17: 開發 YMS302W 抽選稽核紀錄 (YMS302P51) | C17: YMS | D17: 45841 | E17: 45845 | H17: 莊勝淵 | I17: 陸德軒 | J17: =IF(LEN($G17)=0,IF(進度管制表!$D$1>$E17,"延遲","未完成"),IF($E17=$G17,"如期完成",(IF($E17>$G17,"提前完成",IF($E17<$G17,"落後且完成","未完成"))))) -> 未完成 | L17: 應用系統YMS開發測試
A18: 17 | B18: 初測 YMS302W 抽選稽核紀錄 (YMS302P51) | C18: YMS | D18: 45846 | E18: 45846 | H18: 莊勝淵 | J18: =IF(LEN($G18)=0,IF(進度管制表!$D$1>$E18,"延遲","未完成"),IF($E18=$G18,"如期完成",(IF($E18>$G18,"提前完成",IF($E18<$G18,"落後且完成","未完成"))))) -> 未完成 | L18: 應用系統YMS開發測試
A19: 18 | B19: 修正初測問題 YMS302W 抽選稽核紀錄 (YMS302P51) | C19: YMS | D19: 45846 | E19: 45846 | H19: 莊勝淵 | I19: 陸德軒 | J19: =IF(LEN($G19)=0,IF(進度管制表!$D$1>$E19,"延遲","未完成"),IF($E19=$G19,"如期完成",(IF($E19>$G19,"提前完成",IF($E19<$G19,"落後且完成","未完成"))))) -> 未完成 | L19: 應用系統YMS開發測試
A20: 19 | B20: 開發 YMS302W 抽選稽核紀錄 (YMS302P52) | C20: YMS | D20: 45847 | E20: 45849 | H20: 莊勝淵 | I20: 陸德軒 | J20: =IF(LEN($G20)=0,IF(進度管制表!$D$1>$E20,"延遲","未完成"),IF($E20=$G20,"如期完成",(IF($E20>$G20,"提前完成",IF($E20<$G20,"落後且完成","未完成"))))) -> 未完成 | L20: 應用系統YMS開發測試
A21: 20 | B21: 初測 YMS302W 抽選稽核紀錄 (YMS302P52) | C21: YMS | D21: 45852 | E21: 45852 | H21: 莊勝淵 | J21: =IF(LEN($G21)=0,IF(進度管制表!$D$1>$E21,"延遲","未完成"),IF($E21=$G21,"如期完成",(IF($E21>$G21,"提前完成",IF($E21<$G21,"落後且完成","未完成"))))) -> 未完成 | L21: 應用系統YMS開發測試
A22: 21 | B22: 修正初測問題 YMS302W 抽選稽核紀錄 (YMS302P52) | C22: YMS | D22: 45852 | E22: 45852 | H22: 莊勝淵 | I22: 陸德軒 | J22: =IF(LEN($G22)=0,IF(進度管制表!$D$1>$E22,"延遲","未完成"),IF($E22=$G22,"如期完成",(IF($E22>$G22,"提前完成",IF($E22<$G22,"落後且完成","未完成"))))) -> 未完成 | L22: 應用系統YMS開發測試
A23: 22 | B23: 開發 YMS305W 設定系統別 | C23: YMS | D23: 45792 | E23: 45798 | F23: 45792 | G23: 45798 | H23: 莊勝淵 | I23: 陸德軒 | J23: =IF(LEN($G23)=0,IF(進度管制表!$D$1>$E23,"延遲","未完成"),IF($E23=$G23,"如期完成",(IF($E23>$G23,"提前完成",IF($E23<$G23,"落後且完成","未完成"))))) -> 如期完成 | L23: 應用系統YMS開發測試
A24: 23 | B24: 初測 YMS305W 設定系統別 | C24: YMS | D24: 45799 | E24: 45799 | F24: 45799 | G24: 45799 | H24: 莊勝淵 | J24: =IF(LEN($G24)=0,IF(進度管制表!$D$1>$E24,"延遲","未完成"),IF($E24=$G24,"如期完成",(IF($E24>$G24,"提前完成",IF($E24<$G24,"落後且完成","未完成"))))) -> 如期完成 | L24: 應用系統YMS開發測試
A25: 24 | B25: 修正初測問題 YMS305W 設定系統別 | C25: YMS | D25: 45799 | E25: 45799 | F25: 45799 | G25: 45799 | H25: 莊勝淵 | I25: 陸德軒 | J25: =IF(LEN($G25)=0,IF(進度管制表!$D$1>$E25,"延遲","未完成"),IF($E25=$G25,"如期完成",(IF($E25>$G25,"提前完成",IF($E25<$G25,"落後且完成","未完成"))))) -> 如期完成 | L25: 應用系統YMS開發測試
A26: 25 | B26: 開發 YMS310W 設定篩選筆數上限 | C26: YMS | D26: 45800 | E26: 45804 | F26: 45800 | G26: 45804 | H26: 莊勝淵 | I26: 陸德軒 | J26: =IF(LEN($G26)=0,IF(進度管制表!$D$1>$E26,"延遲","未完成"),IF($E26=$G26,"如期完成",(IF($E26>$G26,"提前完成",IF($E26<$G26,"落後且完成","未完成"))))) -> 如期完成 | L26: 應用系統YMS開發測試
A27: 26 | B27: 初測 YMS310W 設定篩選筆數上限 | C27: YMS | D27: 45805 | E27: 45805 | F27: 45805 | G27: 45805 | H27: 莊勝淵 | J27: =IF(LEN($G27)=0,IF(進度管制表!$D$1>$E27,"延遲","未完成"),IF($E27=$G27,"如期完成",(IF($E27>$G27,"提前完成",IF($E27<$G27,"落後且完成","未完成"))))) -> 如期完成 | L27: 應用系統YMS開發測試
A28: 27 | B28: 修正初測問題 YMS310W 設定篩選筆數上限 | C28: YMS | D28: 45805 | E28: 45805 | F28: 45805 | G28: 45805 | H28: 莊勝淵 | I28: 陸德軒 | J28: =IF(LEN($G28)=0,IF(進度管制表!$D$1>$E28,"延遲","未完成"),IF($E28=$G28,"如期完成",(IF($E28>$G28,"提前完成",IF($E28<$G28,"落後且完成","未完成"))))) -> 如期完成 | L28: 應用系統YMS開發測試
A29: 28 | B29: 開發 YMS313W 上傳資料權限設定檔 | C29: YMS | D29: 45806 | E29: 45806 | F29: 45806 | G29: 45806 | H29: 莊勝淵 | I29: 陸德軒 | J29: =IF(LEN($G29)=0,IF(進度管制表!$D$1>$E29,"延遲","未完成"),IF($E29=$G29,"如期完成",(IF($E29>$G29,"提前完成",IF($E29<$G29,"落後且完成","未完成"))))) -> 如期完成 | L29: 應用系統YMS開發測試
A30: 29 | B30: 初測 YMS313W 上傳資料權限設定檔 | C30: YMS | D30: 45810 | E30: 45810 | F30: 45810 | G30: 45810 | H30: 莊勝淵 | J30: =IF(LEN($G30)=0,IF(進度管制表!$D$1>$E30,"延遲","未完成"),IF($E30=$G30,"如期完成",(IF($E30>$G30,"提前完成",IF($E30<$G30,"落後且完成","未完成"))))) -> 如期完成 | L30: 應用系統YMS開發測試
A31: 30 | B31: 修正初測問題 YMS313W 上傳資料權限設定檔 | C31: YMS | D31: 45810 | E31: 45810 | F31: 45810 | G31: 45810 | H31: 莊勝淵 | I31: 陸德軒 | J31: =IF(LEN($G31)=0,IF(進度管制表!$D$1>$E31,"延遲","未完成"),IF($E31=$G31,"如期完成",(IF($E31>$G31,"提前完成",IF($E31<$G31,"落後且完成","未完成"))))) -> 如期完成 | L31: 應用系統YMS開發測試
A32: 31 | B32: 開發 YMS502E 作業紀錄稽核說明表 | C32: YMS | D32: 45853 | E32: 45859 | H32: 莊勝淵 | I32: 陸德軒 | J32: =IF(LEN($G32)=0,IF(進度管制表!$D$1>$E32,"延遲","未完成"),IF($E32=$G32,"如期完成",(IF($E32>$G32,"提前完成",IF($E32<$G32,"落後且完成","未完成"))))) -> 未完成 | L32: 應用系統YMS開發測試
A33: 32 | B33: 初測 YMS502E 作業紀錄稽核說明表 | C33: YMS | D33: 45860 | E33: 45860 | H33: 莊勝淵 | J33: =IF(LEN($G33)=0,IF(進度管制表!$D$1>$E33,"延遲","未完成"),IF($E33=$G33,"如期完成",(IF($E33>$G33,"提前完成",IF($E33<$G33,"落後且完成","未完成"))))) -> 未完成 | L33: 應用系統YMS開發測試
A34: 33 | B34: 修正初測問題 YMS502E 作業紀錄稽核說明表 | C34: YMS | D34: 45860 | E34: 45860 | H34: 莊勝淵 | I34: 陸德軒 | J34: =IF(LEN($G34)=0,IF(進度管制表!$D$1>$E34,"延遲","未完成"),IF($E34=$G34,"如期完成",(IF($E34>$G34,"提前完成",IF($E34<$G34,"落後且完成","未完成"))))) -> 未完成 | L34: 應用系統YMS開發測試
A35: 34 | B35: 開發 YMS610X 定期清檔排程 | C35: YMS | D35: 45792 | E35: 45798 | F35: 45792 | G35: 45798 | H35: 莊勝淵 | I35: 陳珮姍 | J35: =IF(LEN($G35)=0,IF(進度管制表!$D$1>$E35,"延遲","未完成"),IF($E35=$G35,"如期完成",(IF($E35>$G35,"提前完成",IF($E35<$G35,"落後且完成","未完成"))))) -> 如期完成 | L35: 應用系統YMS開發測試
A36: 35 | B36: 初測 YMS610X 定期清檔排程 | C36: YMS | D36: 45799 | E36: 45799 | F36: 45799 | G36: 45804 | H36: 莊勝淵 | J36: =IF(LEN($G36)=0,IF(進度管制表!$D$1>$E36,"延遲","未完成"),IF($E36=$G36,"如期完成",(IF($E36>$G36,"提前完成",IF($E36<$G36,"落後且完成","未完成"))))) -> 落後且完成 | K36: 1.程式開發好佈到乙測出現程式執行環境無法執行shell的錯誤，已與YCM反應再請YCM協助說明要如何處理，影響YMS這個功能開發好佈到乙測無法測試，照預定時程有延遲的狀況。 2.不使用shell，修改YMS程式。 | L36: 應用系統YMS開發測試
A37: 36 | B37: 修正初測問題 YMS610X 定期清檔排程 | C37: YMS | D37: 45799 | E37: 45799 | F37: 45799 | G37: 45804 | H37: 莊勝淵 | I37: 陳珮姍 | J37: =IF(LEN($G37)=0,IF(進度管制表!$D$1>$E37,"延遲","未完成"),IF($E37=$G37,"如期完成",(IF($E37>$G37,"提前完成",IF($E37<$G37,"落後且完成","未完成"))))) -> 落後且完成 | K37: 1.程式開發好佈到乙測出現程式執行環境無法執行shell的錯誤，已與YCM反應再請YCM協助說明要如何處理，影響YMS這個功能開發好佈到乙測無法測試，照預定時程有延遲的狀況。 2.不使用shell，修改YMS程式。 | L37: 應用系統YMS開發測試
A38: 37 | B38: 開發 YMS611X 集中刪檔排程 | C38: YMS | D38: 45800 | E38: 45804 | F38: 45800 | G38: 45804 | H38: 莊勝淵 | I38: 陳珮姍 | J38: =IF(LEN($G38)=0,IF(進度管制表!$D$1>$E38,"延遲","未完成"),IF($E38=$G38,"如期完成",(IF($E38>$G38,"提前完成",IF($E38<$G38,"落後且完成","未完成"))))) -> 如期完成 | L38: 應用系統YMS開發測試
A39: 38 | B39: 初測 YMS611X 集中刪檔排程 | C39: YMS | D39: 45805 | E39: 45805 | F39: 45805 | G39: 45805 | H39: 莊勝淵 | J39: =IF(LEN($G39)=0,IF(進度管制表!$D$1>$E39,"延遲","未完成"),IF($E39=$G39,"如期完成",(IF($E39>$G39,"提前完成",IF($E39<$G39,"落後且完成","未完成"))))) -> 如期完成 | L39: 應用系統YMS開發測試
A40: 39 | B40: 修正初測問題 YMS611X 集中刪檔排程 | C40: YMS | D40: 45805 | E40: 45805 | F40: 45805 | G40: 45805 | H40: 莊勝淵 | I40: 陳珮姍 | J40: =IF(LEN($G40)=0,IF(進度管制表!$D$1>$E40,"延遲","未完成"),IF($E40=$G40,"如期完成",(IF($E40>$G40,"提前完成",IF($E40<$G40,"落後且完成","未完成"))))) -> 如期完成 | L40: 應用系統YMS開發測試
...

Sheet WBS 成員進度管制表
A2: 列標籤 | B2: 計數 - 總工項數 | C2: 計數 -累計已完成工項數 | D2: 本周應完成工項數 | E2: 本周已完成工項數 | F2: 累計應完成工項數 | G2: SPI (累計已完成工項數/累計應完成工項數) | H2: 總落後工項數 | I2: 落後百分比 (總落後工項數/ 總工項數) | J2: 下周應完成工項數 | K2: 剩餘工項數 | L2: 提前完成工項數
A3: 莊勝淵 | B3: =COUNTIF(WBS!H:H,A3) -> 60 | C3: =SUMPRODUCT((WBS!$H:$H=A3)*(WBS!$J:$J="如期完成")+(WBS!$H:$H=A3)*(WBS!$J:$J="提前完成")+(WBS!$H:$H=A3)*(WBS!$J:$J="落後且完成")) -> 16 | D3: {=SUMPRODUCT((WBS!$H:$H=A3)*(WBS!$E:$E<=進度管制表!$D$1)*(WBS!$E:$E>=進度管制表!$B$1))} -> 3 | E3: {=SUMPRODUCT((WBS!$H:$H=A3)*(WBS!$E:$E<=進度管制表!$D$1)*(WBS!$E:$E>=進度管制表!$B$1)*(WBS!$J:$J="如期完成")+(WBS!$H:$H=A3)*(WBS!$E:$E<=進度管制表!$D$1)*(WBS!$E:$E>=進度管制表!$B$1)*(WBS!$J:$J="提前完成")+(WBS!$H:$H=A3)*(WBS!$E:$E<=進度管制表!$D$1)*(WBS!$E:$E>=進度管制表!$B$1)*(WBS!$J:$J="落後且完成"))} -> 3 | F3: =SUMPRODUCT((WBS!$H:$H=A3)*(WBS!$E:$E<=進度管制表!$D$1)) -> 16 | G3: =C3/F3 -> 1 | H3: =SUMPRODUCT((WBS!$H:$H=A3)*(WBS!$J:$J="延遲")) -> 0 | I3: =H3/B3% -> 0 | J3: =SUMPRODUCT((WBS!$H:$H=A3)*(WBS!$E:$E<=進度管制表!$H$1)*(WBS!$E:$E>=進度管制表!$D$1)) -> 10 | K3: =SUMPRODUCT((WBS!$H:$H=A3)*(WBS!$J:$J="未完成")) -> 44 | L3: =SUMPRODUCT((WBS!$H:$H=A3)*(WBS!$J:$J="提前完成")) -> 0

Sheet 進度管制表
A1: 本周統計起日 | B1: =D1-B2 -> 45807 | C1: 本周統計迄日 | D1: 45814 | E1: 本周統計起日 | F1: =D1+1 -> 45815 | G1: 下周統計迄日 | H1: =D1+B2 -> 45821
A2: 周天數 | B2: 7
A4: 列標籤 | B4: 計數 - 總工項數 | C4: 計數 -累計已完成工項數 | D4: 本周應完成工項數 | E4: 本周已完成工項數 | F4: 累計應完成工項數 | G4: SPI (累計已完成工項數/累計應完成工項數) | H4: 總落後工項數 | I4: 落後百分比 (總落後工項數/ 總工項數) | J4: 下周應完成工項數 | K4: 剩餘工項數 | L4: 提前完成工項數
A5: 應用系統YMS開發測試 | B5: =COUNTIF(WBS!L:L,A5) -> 60 | C5: =SUMPRODUCT((WBS!$L:$L=A5)*(WBS!$J:$J="如期完成")+(WBS!$L:$L=A5)*(WBS!$J:$J="提前完成")+(WBS!$L:$L=A5)*(WBS!$J:$J="落後且完成")) -> 16 | D5: =SUMPRODUCT((WBS!$L:$L=A5)*(WBS!$E:$E<=$D$1)*(WBS!$E:$E>=$B$1)) -> 3 | E5: =SUMPRODUCT((WBS!$L:$L=A5)*(WBS!$E:$E<=$D$1)*(WBS!$E:$E>=$B$1)*(WBS!$J:$J="如期完成")+(WBS!$L:$L=A5)*(WBS!$E:$E<=$D$1)*(WBS!$E:$E>=$B$1)*(WBS!$J:$J="提前完成")+(WBS!$L:$L=A5)*(WBS!$E:$E<=$D$1)*(WBS!$E:$E>=$B$1)*(WBS!$J:$J="落後且完成")) -> 3 | F5: =SUMPRODUCT((WBS!$L:$L=A5)*(WBS!$E:$E<=$D$1)) -> 16 | G5: =C5/F5 -> 1 | H5: =SUMPRODUCT((WBS!$L:$L=A5)*(WBS!$J:$J="延遲")) -> 0 | I5: =H5/B5% -> 0 | J5: =SUMPRODUCT((WBS!$L:$L=A5)*(WBS!$E:$E<=$H$1)*(WBS!$E:$E>=$D$1)) -> 10 | K5: =SUMPRODUCT((WBS!$L:$L=A5)*(WBS!$J:$J="未完成")) -> 44 | L5: =SUMPRODUCT((WBS!$L:$L=A5)*(WBS!$J:$J="提前完成")) -> 0

Sheet YMS內部議題追蹤
A1: 序號 | B1: 分組 | C1: 提出日期 | D1: 議題紀要 | E1: 預定完成日期 | F1: 執行現況說明 | G1: 負責人 | H1: 執行狀態 | I1: 實際完成日期 | J1: 備註
A2: 1 | B2: 系統開發維護組 | C2: 45796 | D2: 乙測arcsight環境仍有問題，無法使用，影響YMS程式無法開發的問題。請培棠與中華資安協助處理，確認是arcsight軟體問題還是乙測AWS環境問題。 1. 乙測arcsight依照文腕提供的api文件打打不通: 錯誤訊息顯示arcsight server出現SSLHandshakeException錯誤。 2. arcsight是YMS使用的稽核紀錄資料庫，資料庫無法使用，影響YMS 10個功能，45個工項無法進行開發。 | E2: 45810 | F2: 5/29 1.連線問題經中華資安排除已可連線。 2.文腕回覆憑證要找原廠一起解決，正式環境肯定會遇到這問題，他們會再追蹤。此項目建請結案，後續在中華資安WBS列管追蹤。 5/26 乙測arcsight自5/23下午至今都連不到(ERR_CONNECTION_TIMED_OUT)，請中華資安協助確認arcsight服務狀態是否正常。 5/23 經中華資安重新產製安裝憑證後，開發電腦已可正常連線arcsight。問題如第1點說明，解決方式如第2點說明，排除方式已提供培棠與中華資安參考，後續其他環境的調整再請培棠與中華資安討論進行調整。 1. 經培棠與中華資安莊祥豪確認，現在只要arcsight掛外部產的憑證，執行測試程式就會收到arcsight server回應ssl連線錯誤的錯誤訊息。 2. 中華資安重新產軟體自簽憑證，執行連線測試程式仍出現ssl連線錯誤，於開發電腦執行兩個步驟跳過Java憑證檢核，開發電腦/測試程式已可正常連線arcsight。 3. 後續請培棠與中華資安討論，乙測和甲方環境怎麼調整，讓YMS程式佈上去後能正常連線乙測和甲方環境arcsight server。 | G2: 黃培棠 林文腕 | H2: 已結案
A3: 2 | B3: 系統開發維護組 | C3: 45796 | D3: SDP 自動產檔寫入 ArcSight 的進度追蹤: SDP尚未提供完成應用程式稽核紀錄之寫入，請標準組協助處理。本案應用系統稽核軌跡紀錄由SDP寫入並傳送至arcsight，YMS負責讀產生稽核報表。 | E3: 2025/6/13 2025/6/2 | F3: 6/6 SDP無更新進度，最後問到的進度與5/29相同: 標準組還在調整，尚未完成。 5/29 1. deviceFacility和devicePayloadId這兩個欄位用arcsight介面查會出現Invalid field name的錯誤。經中華資安處理後問題已排除。 2. SDP寫入的欄位值不正確的問題，標準組已修正一版程式，問題是否修正還要等SDP能自動產出APDB日誌檔，中華資料才能抓檔寫入arcsight。標準組還在調整，此項目無法於預定日期完成建請展延至6/13完成。 | G3: 黃培棠 林文腕 | H3: 處理中
A4: 3 | B4: 系統開發維護組 | C4: 45803 | D4: 乙測YCM批次程式執行環境無法執行shell，請YCM協助處理。 | E4: 45817 | F4: 5/29 YCM與標準組討論中尚未定案，5/26經棠鈞科長決議，YMS此功能改成用Java程式處理，不使用shell指令處理。已於5/27完成YMS程式之修改，追趕上進度。請項目建請結案。 5/21 1. YMS610X程式開發好佈到乙測出現"程式執行環境無法執行shell的錯誤"，已與YCM反應再請YCM協助看要怎麼處理。 2. 影響YMS這個功能開發好佈到乙測無法測試，照預定時程有延遲的狀況。 | G4: 蕭勝文 何建興 | H4: 已結案
A5: 4 | B5: 系統開發維護組 | C5: 45813 | D5: 程式佈到乙測連線arcsight不通，導致無法於乙測進行YMS功能測試與文件製作。 | E5: 45827 | F5: 6/5 1. 培棠表示為ArcSight憑證問題，文腕表示他們問完原廠原廠說是中華乙測環境的問題，非ArcSight軟體問題。 2. 請標準組與中華資安討論一下看問題在哪裡如何處理。 | G5: 黃培棠 林文腕 | H5: 處理中
